package Session3.exception;


public class ExceptionDemo {
	
	public static int test() {
		int a=10;
		try {
			return a;
		}
		catch (Exception e) {
			a=20;
			System.out.println("a in catch:"+a);
			return a;
		}
		finally {
			a=30;
			System.out.println("a in finally:"+a);
			return a;
			
		}
	}
	public static void main(String[] args) {
		Calculator obj = new Calculator();
		System.out.println(test());
		try {
			obj.calculation();
		}
		catch (ArithmeticException e) {
			System.out.println(e.getMessage());
		}
	}
}
